Traceback (most recent call last):
  File "/Users/gracehuckins/miniconda3/lib/python3.11/site-packages/jupyter_cache/executors/utils.py", line 58, in single_nb_execution
    executenb(
  File "/Users/gracehuckins/miniconda3/lib/python3.11/site-packages/nbclient/client.py", line 1305, in execute
    return NotebookClient(nb=nb, resources=resources, km=km, **kwargs).execute()
           ^^^^^^^^^^^^^^^^^^^^^^^^^^^^^^^^^^^^^^^^^^^^^^^^^^^^^^^^^^^^^^^^^^^^^
  File "/Users/gracehuckins/miniconda3/lib/python3.11/site-packages/jupyter_core/utils/__init__.py", line 173, in wrapped
    return loop.run_until_complete(inner)
           ^^^^^^^^^^^^^^^^^^^^^^^^^^^^^^
  File "/Users/gracehuckins/miniconda3/lib/python3.11/asyncio/base_events.py", line 653, in run_until_complete
    return future.result()
           ^^^^^^^^^^^^^^^
  File "/Users/gracehuckins/miniconda3/lib/python3.11/site-packages/nbclient/client.py", line 705, in async_execute
    await self.async_execute_cell(
  File "/Users/gracehuckins/miniconda3/lib/python3.11/site-packages/nbclient/client.py", line 1058, in async_execute_cell
    await self._check_raise_for_error(cell, cell_index, exec_reply)
  File "/Users/gracehuckins/miniconda3/lib/python3.11/site-packages/nbclient/client.py", line 914, in _check_raise_for_error
    raise CellExecutionError.from_cell_and_msg(cell, exec_reply_content)
nbclient.exceptions.CellExecutionError: An error occurred while executing the following cell:
------------------
np.random.seed(4)
t = np.linspace(0,1,10001)
s = np.exp(-(t-0.5)**2/2/0.1**2)
s = np.diff(s)
s /= s.std()
s += 2*np.random.randn(len(s))
np.save('./data/noisy_1d_signal_t.npy',t[:-1])
np.save('./data/noisy_1d_signal.npy',s)
------------------


[0;31m---------------------------------------------------------------------------[0m
[0;31mFileNotFoundError[0m                         Traceback (most recent call last)
Cell [0;32mIn[7], line 7[0m
[1;32m      5[0m s [38;5;241m/[39m[38;5;241m=[39m s[38;5;241m.[39mstd()
[1;32m      6[0m s [38;5;241m+[39m[38;5;241m=[39m [38;5;241m2[39m[38;5;241m*[39mnp[38;5;241m.[39mrandom[38;5;241m.[39mrandn([38;5;28mlen[39m(s))
[0;32m----> 7[0m np[38;5;241m.[39msave([38;5;124m'[39m[38;5;124m./data/noisy_1d_signal_t.npy[39m[38;5;124m'[39m,t[:[38;5;241m-[39m[38;5;241m1[39m])
[1;32m      8[0m np[38;5;241m.[39msave([38;5;124m'[39m[38;5;124m./data/noisy_1d_signal.npy[39m[38;5;124m'[39m,s)

File [0;32m~/miniconda3/lib/python3.11/site-packages/numpy/lib/npyio.py:542[0m, in [0;36msave[0;34m(file, arr, allow_pickle, fix_imports)[0m
[1;32m    540[0m     [38;5;28;01mif[39;00m [38;5;129;01mnot[39;00m file[38;5;241m.[39mendswith([38;5;124m'[39m[38;5;124m.npy[39m[38;5;124m'[39m):
[1;32m    541[0m         file [38;5;241m=[39m file [38;5;241m+[39m [38;5;124m'[39m[38;5;124m.npy[39m[38;5;124m'[39m
[0;32m--> 542[0m     file_ctx [38;5;241m=[39m [38;5;28mopen[39m(file, [38;5;124m"[39m[38;5;124mwb[39m[38;5;124m"[39m)
[1;32m    544[0m [38;5;28;01mwith[39;00m file_ctx [38;5;28;01mas[39;00m fid:
[1;32m    545[0m     arr [38;5;241m=[39m np[38;5;241m.[39masanyarray(arr)

[0;31mFileNotFoundError[0m: [Errno 2] No such file or directory: './data/noisy_1d_signal_t.npy'

